<!-- 
    需求: 创建机器人模型，底盘为长方体，
         在长方体的前面添加一摄像头，
         摄像头可以沿着 Z 轴 360 度旋转

 -->
<robot name="my_car">
    <!-- 添加一个极小的link，关联初始link与base_link -->
    <link name="base_footprint">
        <visual>
            <geometry>
                <box size="0.001 0.001 0.001" />
            </geometry>
        </visual>
    </link>


    <!-- 底盘 -->
    <link name="base_link">
        <visual>
            <geometry>
                <box size="0.5 0.2 0.1" />
            </geometry>
            <origin xyz="0 0 0" rpy="0 0 0" />
            <material name="blue">
                <color rgba="0 0 1.0 0.5" />
            </material>
        </visual>
    </link>

    <!-- 摄像头 -->
    <link name="camera">
        <visual>
            <geometry>
                <box size="0.02 0.05 0.05" />
            </geometry>
            <origin xyz="0 0 0" rpy="0 0 0" />
            <material name="red">
                <color rgba="1 0 0 0.5" />
            </material>
        </visual>
    </link>

    <!-- 关节 -->
    <joint name="camera2baselink" type="continuous">
        <parent link="base_link"/>
        <child link="camera" />
        <!-- 需要计算两个 link 的物理中心之间的偏移量 -->
        <origin xyz="0.2 0 0.075" rpy="0 0 0" />
        <!-- 设置关节旋转参考坐标系 -->
        <axis xyz="0 0 1" />
    </joint>

    <!-- 关联base_footprint 与base_link -->
    <joint name="link2footprint" type="fixed">
        <parent link="base_footprint"/>
        <child link="base_link" />
        <!-- 需要计算两个 link 的物理中心之间的偏移量 -->
        <origin xyz="0 0 0.05" rpy="0 0 0" />
        <!-- 设置关节旋转参考坐标系 -->
        <axis xyz="0 0 0" />
    </joint>

</robot>